Workbook

Sheet RELATORIO
A1: CORPO DE BOMBEIROS MILITAR DO AMAZONAS | AQ1: DATA DE HOJE
A2: RELATÓRIO DE OCORRÊNCIAS 2026
A3: 1 | B3: Comandante do Incidente: | G3: CEL QOBM BORGES | W3: Período Operacional: | AD3: =TEXT(AQ3,"DD") -> 02 | AE3: =UPPER("/ "&TEXT(AQ3,"MMM")&" / 2026 - 8h00") -> / AGO / 2026 - 8H00 | AQ3: 46236
A4: 2 | B4: Chefe de Operações Capital: | G4: CEL QOBM MENEZES | W4: Próximo Período Operacional: | AD4: =TEXT(AQ7,"DD") -> 03 | AE4: =UPPER("/ "&TEXT(AQ7,"MMM")&" / 2026 - 8h00") -> / AGO / 2026 - 8H00
A5: 3 | B5: Chefe de Operações Interior: | G5: CEL QOBM MONTEIRO | W5: Reunião de Planejamento: | AD5: =TEXT($AQ$3,"DD") -> 02 | AE5: =UPPER("/ "&TEXT(AQ3,"MMM")&" / 2026 - 8h15") -> / AGO / 2026 - 8H15 | AQ5: =AQ3-1 -> 46235 | AW5: não mexer
A6: 4 | B6: Coordenador da Sala de Situação: | G6: TC QOBM FERREIRA | W6: Reunião de Briefing: | AD6: =TEXT($AQ$3,"DD") -> 02 | AE6: =UPPER("/ "&TEXT(AQ3,"MMM")&" / 2026 - 8h30") -> / AGO / 2026 - 8H30
A7: 5 | AQ7: =AQ3+1 -> 46237 | AW7: não mexer
A9: EFETIVO | G9: EFETIVO | P9: EFETIVO | Y9: RESUMO EFETIVO
A10: Nº | B10: MUNICÍPIO | C10: SERV. ORDINÁRIO | D10: SEG | E10: BRIGADISTA | G10: MUNICÍPIO | L10: SERV. ORDINÁRIO | M10: SEG | N10: BRIGADISTA | P10: BASES TEMPORÁRIAS | U10: SERV. ORDINÁRIO | V10: SEG | W10: BRIGADISTA | Y10: MISSÃO | AB10: CAPITAL | AC10: INTERIOR | AE10: TOTAL
A11: 1 | B11: =B63 -> Manaus | C11: 114 | D11: 10 | E11: 0 | G11: Manaquiri | L11: 4 | N11: 0 | P11: Boca do Acre | U11: 8 | W11: 0 | Y11: SV ORD | AB11: =SUM(C11) -> 114 | AC11: =SUM(C12:C23,L11:L23,U11:U16) -> 217 | AE11: =SUM(AB11:AD11) -> 331
B12: Apuí | C12: 12 | E12: 11 | G12: Manacapuru | L12: 6 | N12: 0 | P12: Borba | U12: 3 | W12: 0 | Y12: SEG | AB12: =SUM(D11) -> 10 | AC12: =SUM(D12:D23,M11:M23,V11:V16) -> 6 | AE12: =SUM(AB12:AD12) -> 16
B13: =B65 -> Atalaia do Norte | C13: 7 | E13: 0 | G13: Manicoré | L13: 13 | N13: 12 | P13: Canutama | U13: 5 | W13: 0 | Y13: BRIGADISTA | AB13: =SUM(E11) -> 0 | AC13: =SUM(E12:E23,N11:N23,W11:W16) -> 90 | AE13: =SUM(AB13:AD13) -> 90
B14: =B66 -> Autazes | C14: 14 | E14: 13 | G14: Maués | L14: 11 | M14: 2 | N14: 13 | P14: Careiro | U14: 5 | W14: 0 | Y14: TOTAL | AB14: =SUM(AB11:AB13) -> 124 | AC14: =SUM(AC11:AD13) -> 313 | AE14: =SUM(AE11:AF13) -> 437
B15: Barcelos | C15: 7 | E15: 12 | G15: Novo Airão | L15: 3 | N15: 2 | P15: Nhamundá | U15: 2 | W15: 0
B16: Coari | C16: 12 | E16: 0 | G16: Novo Aripuanã | L16: 12 | M16: 2 | N16: 7 | P16: Uricurituba | U16: 0 | W16: 0
B17: Envira | C17: 4 | E17: 0 | G17: Parintins | L17: 8 | N17: 0 | P17: =B135 -> TOTAL | U17: =SUM(U11:U16) -> 23 | V17: =SUM(V11:V16) -> 0 | W17: =SUM(W11:W16) -> 0
B18: Humaitá | C18: 21 | E18: 0 | G18: Presidente Figueiredo | L18: 6 | N18: 0
A19: 2 | B19: Iranduba | C19: 6 | D19: 2 | E19: 0 | G19: Rio Preto da Eva | L19: 5 | N19: 2
A20: 3 | B20: Itacoatiara | C20: 3 | E20: 0 | G20: Tabatinga | L20: 5 | N20: 1 | O20: [
B21: Itapiranga | C21: 7 | E21: 12
B22: Jutaí | C22: 5 | E22: 0 | G22: Tapauá | L22: 4 | N22: 0
B23: Lábrea | C23: 13 | E23: 0 | G23: Tefé | L23: 6 | N23: 5
G24: Total | L24: =SUM(C11:C23,L11:L23) -> 308 | M24: =SUM(D11:D23,M11:M23) -> 16 | N24: =SUM(E11:E23,N11:N23) -> 90
A26: RECURSOS | AD26: RESUMO RECURSOS | AJ26: RESUMO RECURSOS
A27: Nº | B27: MUNICÍPIO | C27: ABT | D27: AT | E27: ATP | F27: ATA | G27: ABF | H27: ATF | I27: ABS | J27: PIPA | K27: DOSA | L27: CRS | M27: AR | N27: UR | O27: GSE | P27: MT | Q27: TA | R27: EMBARCAÇÃO | S27: PICAPE FN | T27: PICAPE MUNI | U27: AUTOARP | V27: PICAPE ESFRON | W27: HELICÓPTERO | X27: AVIÃO | Y27: JET SKI | Z27: QUADRICICLO | AA27: AEM | AB27: TOTAL | AD27: RECURSOS | AG27: QTD | AJ27: RECURSOS | AM27: QTD
A28: 1 | B28: =B63 -> Manaus | C28: 5 | F28: 1 | G28: 1 | K28: 3 | L28: 1 | M28: 6 | N28: 6 | O28: 3 | R28: 1 | U28: 1 | Y28: 1 | Z28: 1 | AB28: =SUM(C28:AA28) -> 30 | AD28: =C27 -> ABT | AG28: =C59 -> 17 | AJ28: =P27 -> MT | AM28: =P59 -> 11
B29: Apuí | H29: 1 | M29: 2 | AB29: =SUM(C29:AA29) -> 3 | AD29: =D27 -> AT | AG29: =D59 -> 2 | AJ29: =Q27 -> TA | AM29: =Q59 -> 0
B30: =B65 -> Atalaia do Norte | H30: 1 | AB30: =SUM(C30:AA30) -> 1 | AD30: =AA27 -> AEM | AG30: =AA59 -> 0 | AJ30: =Z27 -> QUADRICICLO | AM30: =Z59 -> 1
B31: =B66 -> Autazes | H31: 1 | M31: 2 | AB31: =SUM(C31:AA31) -> 3 | AD31: =E27 -> ATP | AG31: =E59 -> 2 | AJ31: =R27 -> EMBARCAÇÃO | AM31: =R59 -> 14
B32: Barcelos | H32: 1 | M32: 1 | AB32: =SUM(C32:AA32) -> 2 | AD32: =F27 -> ATA | AG32: =F59 -> 3 | AJ32: =S27 -> PICAPE FN | AM32: =S59 -> 0
B33: Boca do Acre | H33: 1 | M33: 1 | AB33: =SUM(C33:AA33) -> 2 | AD33: =G27 -> ABF | AG33: =G59 -> 2 | AJ33: =T27 -> PICAPE MUNI | AM33: =T59 -> 0
B34: =B69 -> Borba | F34: 1 | AB34: =SUM(C34:AA34) -> 1 | AD34: =H27 -> ATF | AG34: =H59 -> 17 | AJ34: =U27 -> AUTOARP | AM34: =U59 -> 1
B35: Canutama | M35: 1 | AB35: =SUM(C35:AA35) -> 1 | AD35: =I27 -> ABS | AG35: =I59 -> 2 | AJ35: =V27 -> PICAPE ESFRON | AM35: =V59 -> 0
B36: Careiro | M36: 1 | AB36: =SUM(C36:AA36) -> 1 | AD36: =J27 -> PIPA | AG36: =J59 -> 0 | AJ36: =W27 -> HELICÓPTERO | AM36: =W59 -> 0
B37: Coari | H37: 1 | M37: 1 | AB37: =SUM(C37:AA37) -> 2 | AD37: =K27 -> DOSA | AG37: =K59 -> 5 | AJ37: =X27 -> AVIÃO | AM37: =X59 -> 0
B38: Envira | H38: 1 | AB38: =SUM(C38:AA38) -> 1 | AD38: =L27 -> CRS | AG38: =L59 -> 1 | AJ38: =Y27 -> JET SKI | AM38: =Y59 -> 5
A39: 2 | B39: =B74 -> Humaitá | G39: 1 | M39: 1 | N39: 1 | R39: 2 | AB39: =SUM(C39:AA39) -> 5 | AD39: =M27 -> AR | AG39: =M59 -> 39
A40: 3 | B40: =B75 -> Iranduba | C40: 1 | M40: 2 | N40: 1 | P40: 1 | AB40: =SUM(C40:AA40) -> 5 | AD40: =N27 -> UR | AG40: =N59 -> 17
A41: 4 | B41: =B76 -> Itacoatiara | C41: 1 | I41: 1 | M41: 1 | N41: 1 | P41: 2 | R41: 1 | AB41: =SUM(C41:AA41) -> 7 | AD41: =O27 -> GSE | AG41: =O59 -> 5
B42: Itapiranga | H42: 1 | M42: 1 | AB42: =SUM(C42:AA42) -> 2 | AD42: TOTAL RECURSOS | AM42: =SUM(AG28:AH41,AM28:AN41) -> 144
...

Sheet DADOS
A1: Carimbo de data/hora | B1: Endereço de e-mail | C1: INFORME SUA CIDADE DE ATUAÇÃO | D1: INFORME A DATA DA OCORRÊNCIA | E1: INFORME O HORÁRIO DA OCORRÊNCIA | F1: INFORME A NATUREZA DA OCORRÊNCIA | G1: INFORME A QUANTIDADE DE FOCOS DE INCÊNDIO NA OCORRÊNCIA | H1: INFORME AS COORDENADAS GEOGRÁFICAS DA OCORRÊNCIA | I1: INFORME O ENDEREÇO DA OCORRÊNCIA | J1: INFORME A ÁREA QUEIMADA (EM METROS QUADRADOS) | K1: INFORME A QUANTIDADE DE ÁGUA UTILIZADA (EM LITROS) | L1: ADMINISTRAÇÃO (QTD DE EFETIVO) | M1: SERVIÇO ORDINÁRIO (QTD DE EFETIVO) | N1: SEG (QTD DE EFETIVO) | O1: CÉU LIMPO (QTD DE EFETIVO) | P1: ACEIRO (QTD DE EFETIVO) | Q1: FORÇA NACIONAL (QTD DE EFETIVO) | R1: BRIGADISTA FLORESTAL (QTD DE EFETIVO) | S1: BRIGADISTA CIVIL (QTD DE EFETIVO) | T1: DEFESA CIVIL (QTD DE EFETIVO) | U1: TRIPULANTES DE AVIÃO (QTD DE EFETIVO) | V1: OUTROS (QTD DE EFETIVO) | W1: VIATURA ABT (QTD EMPREGADA) | X1: VIATURA AT (QTD EMPREGADA) | Y1: VIATURA ATP (QTD EMPREGADA) | Z1: VIATURA ATA (QTD EMPREGADA) | AA1: VIATURA ABF (QTD EMPREGADA) | AB1: VIATURA ABS (QTD EMPREGADA) | AC1: VIATURA PIPA (QTD EMPREGADA) | AD1: VIATURA DOSA (QTD EMPREGADA) | AE1: VIATURA CRS (QTD EMPREGADA) | AF1: VIATURA AR (QTD EMPREGADA) | AG1: VIATURA ATM (QTD EMPREGADA) | AH1: VIATURA UR (QTD EMPREGADA) | AI1: VIATURA MT (QTD EMPREGADA) | AJ1: VIATURA TA (QTD EMPREGADA) | AK1: VIATURA EMBARCAÇÃO (QTD EMPREGADA) | AL1: VIATURA PICAPE FN (QTD EMPREGADA) | AM1: VIATURA PICAPE MUN (QTD EMPREGADA) | AN1: VIATURA PICAPE SSP (QTD EMPREGADA) | AO1: VIATURA HELICÓPTERO (QTD EMPREGADA) | AP1: VIATURA AVIÃO (QTD EMPREGADA) | AQ1: VIATURA AEM (QTD EMPREGADA) | AR1: INFORME O NÚMERO DA OCORRÊNCIA (GRUPO CBI EM AÇÃO) | AS1: INFORME O NÚMERO DA OCORRÊNCIA (GRUPO OPERAÇÃO ACEIRO)
A2: 45528.682 | B2: salacbmam@gmail.com | C2: Manaus | D2: 45446 | F2: INCÊNDIO EM EDIFICAÇÕES
A3: 45528.685 | B3: salacbmam@gmail.com | C3: Manaus | D3: 45446 | F3: INCÊNDIO EM EDIFICAÇÕES
A4: 45528.686 | B4: salacbmam@gmail.com | C4: Manaus | D4: 45447 | F4: INCÊNDIO EM EDIFICAÇÕES
A5: 45528.687 | B5: salacbmam@gmail.com | C5: Manaus | D5: 45448 | F5: INCÊNDIO EM EDIFICAÇÕES
A6: 45484.752 | B6: salacbmam@gmail.com | C6: Humaitá | D6: 45449 | E6: 0.58333333 | F6: INCÊNDIO FLORESTAL | I6: Rua Projetada, zona rural | J6: 10000 | K6: 1000 | P6: 3
A7: 45484.759 | B7: salacbmam@gmail.com | C7: Humaitá | D7: 45449 | E7: 0.61111111 | F7: INCÊNDIO FLORESTAL | I7: Invasão atrás do conjunto Rio madeira s/n , Área Rural | J7: 10000 | K7: 1500 | P7: 3
A8: 45484.761 | B8: salacbmam@gmail.com | C8: Humaitá | D8: 45449 | E8: 0.64444444 | F8: INCÊNDIO FLORESTAL | I8: Ramal da comunidade do Uxi Bairro: Zona rural | J8: 20000 | K8: 2000 | P8: 3
A9: 45528.688 | B9: salacbmam@gmail.com | C9: Manaus | D9: 45449 | F9: INCÊNDIO EM EDIFICAÇÕES
A10: 45528.691 | B10: salacbmam@gmail.com | C10: Manaus | D10: 45450 | F10: INCÊNDIO FLORESTAL
A11: 45528.691 | B11: salacbmam@gmail.com | C11: Manaus | D11: 45450 | F11: INCÊNDIO EM EDIFICAÇÕES
A12: 45528.693 | B12: salacbmam@gmail.com | C12: Manaus | D12: 45451 | F12: INCÊNDIO FLORESTAL
A13: 45528.694 | B13: salacbmam@gmail.com | C13: Manaus | D13: 45452 | F13: INCÊNDIO EM EDIFICAÇÕES
A14: 45528.694 | B14: salacbmam@gmail.com | C14: Manaus | D14: 45452 | F14: INCÊNDIO EM EDIFICAÇÕES
A15: 45528.696 | B15: salacbmam@gmail.com | C15: Parintins | D15: 45452 | F15: INCÊNDIO EM EDIFICAÇÕES
A16: 45528.753 | B16: salacbmam@gmail.com | C16: Presidente Figueiredo | D16: 45453 | F16: INCÊNDIO FLORESTAL
A17: 45528.754 | B17: salacbmam@gmail.com | C17: Manaus | D17: 45453 | F17: INCÊNDIO EM EDIFICAÇÕES
A18: 45528.754 | B18: salacbmam@gmail.com | C18: Manaus | D18: 45453 | F18: INCÊNDIO EM EDIFICAÇÕES
A19: 45475.62 | B19: wagnneerrd@gmail.com | C19: Humaitá | D19: 45454 | E19: 0.8125 | F19: INCÊNDIO FLORESTAL | I19: Rua 2. Residencial Santa Clara. Bairro São Cristóvão | K19: 1000 | L19: 1 | M19: 3 | N19: 0 | O19: 0 | P19: 3 | Q19: 0 | R19: 0 | S19: 0 | T19: 0 | AA19: 1
A20: 45528.772 | B20: salacbmam@gmail.com | C20: Manaus | D20: 45454 | F20: INCÊNDIO EM EDIFICAÇÕES
A21: 45528.775 | B21: salacbmam@gmail.com | C21: Manaus | D21: 45454 | F21: INCÊNDIO FLORESTAL
A22: 45528.775 | B22: salacbmam@gmail.com | C22: Manaus | D22: 45454 | F22: INCÊNDIO FLORESTAL
A23: 45475.619 | B23: joaofelipe292@gmail.com | C23: Boca do Acre | D23: 45455 | E23: 0.58194444 | F23: INCÊNDIO FLORESTAL | H23: 8.77968242S 67.32831918W | I23: Rodovia Wilson Pinheiro, Bairro platô do Piquiá nº 11011-C | J23: 1000 | K23: 600 | P23: 04 | AF23: 1
A24: 45528.778 | B24: salacbmam@gmail.com | C24: Parintins | D24: 45455 | F24: INCÊNDIO EM EDIFICAÇÕES
A25: 45528.779 | B25: salacbmam@gmail.com | C25: Manacapuru | D25: 45455 | F25: INCÊNDIO FLORESTAL
A26: 45528.781 | B26: salacbmam@gmail.com | C26: Boca do Acre | D26: 45455 | F26: INCÊNDIO FLORESTAL
A27: 45528.781 | B27: salacbmam@gmail.com | C27: Boca do Acre | D27: 45455 | F27: INCÊNDIO FLORESTAL
A28: 45528.781 | B28: salacbmam@gmail.com | C28: Boca do Acre | D28: 45455 | F28: INCÊNDIO FLORESTAL
A29: 45528.781 | B29: salacbmam@gmail.com | C29: Boca do Acre | D29: 45455 | F29: INCÊNDIO FLORESTAL
A30: 45528.781 | B30: salacbmam@gmail.com | C30: Boca do Acre | D30: 45455 | F30: INCÊNDIO FLORESTAL
A31: 45528.781 | B31: salacbmam@gmail.com | C31: Boca do Acre | D31: 45455 | F31: INCÊNDIO FLORESTAL
A32: 45528.781 | B32: salacbmam@gmail.com | C32: Boca do Acre | D32: 45455 | F32: INCÊNDIO FLORESTAL
A33: 45528.784 | B33: salacbmam@gmail.com | C33: Manaus | D33: 45456 | F33: INCÊNDIO EM EDIFICAÇÕES
A34: 45528.784 | B34: salacbmam@gmail.com | C34: Manaus | D34: 45456 | F34: INCÊNDIO EM EDIFICAÇÕES
A35: 45528.784 | B35: salacbmam@gmail.com | C35: Manaus | D35: 45456 | F35: INCÊNDIO EM EDIFICAÇÕES
... A38: 45528.798 | B38: salacbmam@gmail.com | C38: Manaus | D38: 45458 | F38: INCÊNDIO EM EDIFICAÇÕES
A39: 45528.799 | C39: Itacoatiara | D39: 45459 | F39: INCÊNDIO EM EDIFICAÇÕES
A40: 45475.794 | B40: pgarciasbm@gmail.com | C40: Humaitá | D40: 45459 | E40: 0.62361111 | F40: INCÊNDIO FLORESTAL | G40: 3 | H40: -7.52536"S,-63.04117"W | I40: Rua Bom Conselho, conjunto Habitacional Uruapiara | J40: 300 | K40: 2500 | L40: 4 | M40: 2 | N40: 00 | O40: 00 | P40: 2 | Q40: 00 | R40: 00 | S40: 00 | T40: 00 | U40: 00 | V40: 00 | W40: 00 | X40: 00 | Y40: 00 | Z40: 00 | AA40: 00 | AB40: 1 | AC40: 00 | AD40: 00 | AE40: 00 | AF40: 00 | AG40: 00 | AH40: 00 | AI40: 00 | AJ40: 00 | AK40: 00 | AL40: 00 | AM40: 00 | AN40: 00 | AO40: 00 | AP40: 00 | AQ40: 00
A41: 45528.799 | C41: Humaitá | D41: 45459 | F41: INCÊNDIO FLORESTAL | G41: 1
A42: 45528.799 | C42: Humaitá | D42: 45459 | F42: INCÊNDIO FLORESTAL | G42: 1
...

Sheet DADOS antigos
A1: Carimbo de data/hora | B1: Endereço de e-mail | C1: INFORME SUA CIDADE DE ATUAÇÃO | D1: INFORME A DATA DA OCORRÊNCIA | E1: INFORME O HORÁRIO DA OCORRÊNCIA | F1: INFORME A NATUREZA DA OCORRÊNCIA | G1: INFORME A QUANTIDADE DE FOCOS DE INCÊNDIO NA OCORRÊNCIA | H1: INFORME AS COORDENADAS GEOGRÁFICAS DA OCORRÊNCIA | I1: INFORME O ENDEREÇO DA OCORRÊNCIA | J1: INFORME A ÁREA QUEIMADA (EM METROS QUADRADOS) | K1: INFORME A QUANTIDADE DE ÁGUA UTILIZADA (EM LITROS) | L1: ADMINISTRAÇÃO (QTD DE EFETIVO) | M1: SERVIÇO ORDINÁRIO (QTD DE EFETIVO) | N1: SEG (QTD DE EFETIVO) | O1: CÉU LIMPO (QTD DE EFETIVO) | P1: ACEIRO (QTD DE EFETIVO) | Q1: FORÇA NACIONAL (QTD DE EFETIVO) | R1: BRIGADISTA FLORESTAL (QTD DE EFETIVO) | S1: BRIGADISTA CIVIL (QTD DE EFETIVO) | T1: DEFESA CIVIL (QTD DE EFETIVO) | U1: TRIPULANTES DE AVIÃO (QTD DE EFETIVO) | V1: OUTROS (QTD DE EFETIVO) | W1: VIATURA ABT (QTD EMPREGADA) | X1: VIATURA AT (QTD EMPREGADA) | Y1: VIATURA ATP (QTD EMPREGADA) | Z1: VIATURA ATA (QTD EMPREGADA) | AA1: VIATURA ABF (QTD EMPREGADA) | AB1: VIATURA ABS (QTD EMPREGADA) | AC1: VIATURA PIPA (QTD EMPREGADA) | AD1: VIATURA DOSA (QTD EMPREGADA) | AE1: VIATURA CRS (QTD EMPREGADA) | AF1: VIATURA AR (QTD EMPREGADA) | AG1: VIATURA ATM (QTD EMPREGADA) | AH1: VIATURA UR (QTD EMPREGADA) | AI1: VIATURA MT (QTD EMPREGADA) | AJ1: VIATURA TA (QTD EMPREGADA) | AK1: VIATURA EMBARCAÇÃO (QTD EMPREGADA) | AL1: VIATURA PICAPE FN (QTD EMPREGADA) | AM1: VIATURA PICAPE MUN (QTD EMPREGADA) | AN1: VIATURA PICAPE SSP (QTD EMPREGADA) | AO1: VIATURA HELICÓPTERO (QTD EMPREGADA) | AP1: VIATURA AVIÃO (QTD EMPREGADA) | AQ1: VIATURA AEM (QTD EMPREGADA) | AR1: INFORME O NÚMERO DA OCORRÊNCIA (GRUPO CBI EM AÇÃO) | AS1: INFORME O NÚMERO DA OCORRÊNCIA (GRUPO OPERAÇÃO ACEIRO)
A2: 45484.752 | B2: salacbmam@gmail.com | C2: Humaitá | D2: 45449 | E2: 0.58333333 | F2: INCÊNDIO FLORESTAL | G2: 1 | I2: Rua Projetada, zona rural | J2: 10000 | K2: 1000 | P2: 3
A3: 45484.759 | B3: salacbmam@gmail.com | C3: Humaitá | D3: 45449 | E3: 0.61111111 | F3: INCÊNDIO FLORESTAL | G3: 1 | I3: Invasão atrás do conjunto Rio madeira s/n , Área Rural | J3: 10000 | K3: 1500 | P3: 3
A4: 45484.761 | B4: salacbmam@gmail.com | C4: Humaitá | D4: 45449 | E4: 0.64444444 | F4: INCÊNDIO FLORESTAL | G4: 1 | I4: Ramal da comunidade do Uxi Bairro: Zona rural | J4: 20000 | K4: 2000 | P4: 3
A5: 45484.772 | B5: salacbmam@gmail.com | C5: Parintins | D5: 45451 | E5: 0.86111111 | F5: INCÊNDIO EM EDIFICAÇÕES | I5: Rua Wilson Cursino , n° 3756 Bairro: Itaúna 2 | M5: 5
A6: 45475.62 | B6: wagnneerrd@gmail.com | C6: Humaitá | D6: 45454 | E6: 0.8125 | F6: INCÊNDIO FLORESTAL | G6: 6 | I6: Rua 2. Residencial Santa Clara. Bairro São Cristóvão | K6: 1000 | L6: 1 | M6: 3 | N6: 0 | O6: 0 | P6: 3 | Q6: 0 | R6: 0 | S6: 0 | T6: 0 | AA6: 1
A7: 45475.638 | B7: wagnneerrd@gmail.com | C7: Humaitá | D7: 45454 | E7: 0.81527778 | F7: INCÊNDIO FLORESTAL | G7: 8 | J7: 500 | K7: 1000 | P7: 6 | Q7: 12 | AA7: 1
A8: 45475.619 | B8: joaofelipe292@gmail.com | C8: Boca do Acre | D8: 45455 | E8: 0.58194444 | F8: INCÊNDIO FLORESTAL | G8: 2 | H8: 8.77968242S 67.32831918W | I8: Rodovia Wilson Pinheiro, Bairro platô do Piquiá nº 11011-C | J8: 1000 | K8: 600 | P8: 04 | AF8: 1
A9: 45475.751 | B9: pgarciasbm@gmail.com | C9: Humaitá | D9: 45455 | E9: 0.51805556 | F9: INCÊNDIO FLORESTAL | G9: 3 | H9: -7.52034"S,--63.03682 | I9: Rua Dom José, São Sebastião | J9: 50 | K9: 700 | L9: 4 | M9: 6 | N9: 00 | O9: 00 | P9: 6 | Q9: 00 | R9: 00 | S9: 00 | T9: 00 | U9: 00 | V9: 00 | W9: 00 | X9: 00 | Y9: 00 | Z9: 00 | AA9: 1 | AB9: 1 | AC9: 00 | AD9: 00 | AE9: 00 | AF9: 1 | AG9: 00 | AH9: 00 | AI9: 2 | AJ9: 00 | AK9: 1 | AL9: 3 | AM9: 00 | AN9: 00 | AO9: 00 | AP9: 00 | AQ9: 00
A10: 45475.758 | B10: pgarciasbm@gmail.com | C10: Humaitá | D10: 45455 | E10: 0.57291667 | F10: INCÊNDIO FLORESTAL | G10: 15 | H10: -7.52194"S,--63.03833"W | I10: Br 230, km 1 | J10: 1000 | K10: 4000 | L10: 4 | M10: 6 | N10: 00 | O10: 00 | P10: 6 | Q10: 6 | R10: 00 | S10: 00 | T10: 00 | U10: 00 | V10: 00 | W10: 00 | X10: 00 | Y10: 00 | Z10: 00 | AA10: 2 | AB10: 1 | AC10: 00 | AD10: 00 | AE10: 00 | AF10: 1 | AG10: 00 | AH10: 00 | AI10: 2 | AJ10: 00 | AK10: 1 | AL10: 03 | AM10: 00 | AN10: 00 | AO10: 00 | AP10: 09 | AQ10: 00
A11: 45475.763 | B11: pgarciasbm@gmail.com | C11: Humaitá | D11: 45455 | E11: 0.54583333 | F11: INCÊNDIO FLORESTAL | G11: 3 | H11: -7.52633"S,-63.03694 | I11: Rua Santa Civita, São Cristóvão | J11: 400 | K11: 1000 | L11: 4 | M11: 6 | N11: 00 | O11: 00 | P11: 6 | Q11: 6 | R11: 00 | S11: 00 | T11: 00 | U11: 0/ | V11: 00 | W11: 00 | X11: 00 | Y11: 00 | Z11: 00 | AA11: 2 | AB11: 1 | AC11: 00 | AD11: 00 | AE11: 00 | AF11: 1 | AG11: 00 | AH11: 00 | AI11: 2 | AJ11: 00 | AK11: 1 | AL11: 03 | AM11: 00 | AN11: 00 | AO11: 00 | AP11: 00 | AQ11: 00
A12: 45475.77 | B12: pgarciasbm@gmail.com | C12: Humaitá | D12: 45455 | E12: 0.60416667 | F12: INCÊNDIO FLORESTAL | G12: 10 | H12: -7.54234"S,--63.04496 | I12: Rua Castanheira, loteamento Santa Clara | J12: 1000 | K12: 4000 | L12: 4 | M12: 6 | N12: 00 | O12: 00 | P12: 6 | Q12: 6 | R12: 00 | S12: 00 | T12: 00 | U12: 00 | V12: 00 | W12: 00 | X12: 00 | Y12: 00 | Z12: 00 | AA12: 2 | AB12: 1 | AC12: 00 | AD12: 00 | AE12: 00 | AF12: 1 | AG12: 00 | AH12: 00 | AI12: 2 | AJ12: 00 | AK12: 1 | AL12: 03 | AM12: 00 | AN12: 00 | AO12: 00 | AP12: 00 | AQ12: 00
A13: 45475.629 | B13: joaofelipe292@gmail.com | C13: Boca do Acre | D13: 45456 | E13: 0.61805556 | F13: INCÊNDIO FLORESTAL | G13: 15 | H13: 8.7799141S 67.32562544W | I13: bairro concordia | J13: 250 | K13: 200 | P13: 4 | AF13: 1
A14: 45475.634 | B14: joaofelipe292@gmail.com | C14: Boca do Acre | D14: 45456 | E14: 0.61805556 | F14: INCÊNDIO FLORESTAL | G14: 15 | H14: 08°48'14.06" S 67°16'12.59" W 140 | I14: ramal do Ditão, proximo ao aterro sanitário | J14: 10000 | K14: 600 | P14: 04 | AF14: 1
A15: 45475.776 | B15: pgarciasbm@gmail.com | C15: Humaitá | D15: 45456 | E15: 0.93333333 | F15: INCÊNDIO FLORESTAL | G15: 2 | H15: -7.54172,"S,--63.06588"W | I15: Br 230, km 5 | J15: 50 | K15: 700 | L15: 4 | M15: 6 | N15: 00 | O15: 00 | P15: 6 | Q15: 00 | R15: 00 | S15: 00 | T15: 00 | U15: 00 | V15: 00 | W15: 00 | X15: 00 | Y15: 00 | Z15: 00 | AA15: 2 | AB15: 1 | AC15: 00 | AD15: 00 | AE15: 00 | AF15: 1 | AG15: 00 | AH15: 00 | AI15: 2 | AJ15: 00 | AK15: 1 | AL15: 00 | AM15: 00 | AN15: 00 | AO15: 00 | AP15: 00 | AQ15: 00
A16: 45475.783 | B16: pgarciasbm@gmail.com | C16: Humaitá | D16: 45458 | E16: 0.70833333 | F16: INCÊNDIO FLORESTAL | G16: 3 | H16: -7.49291"S,-63.02613"W | I16: Rua da Portobras, São Domingos Sávio | J16: 50 | K16: 2500 | L16: 4 | M16: 6 | N16: 00 | O16: 00 | P16: 6 | Q16: 00 | R16: 00 | S16: 00 | T16: 00 | U16: 00 | V16: 00 | W16: 00 | X16: 00 | Y16: 00 | Z16: 00 | AA16: 0 | AB16: 1 | AC16: 00 | AD16: 00 | AE16: 00 | AF16: 00 | AG16: 00 | AH16: 00 | AI16: 00 | AJ16: 00 | AK16: 00 | AL16: 00 | AM16: 00 | AN16: 00 | AO16: 00 | AP16: 00 | AQ16: 00
A17: 45475.788 | B17: pgarciasbm@gmail.com | C17: Humaitá | D17: 45458 | E17: 0.70833333 | F17: INCÊNDIO FLORESTAL | G17: 10 | H17: -7.50706"S,-63.04240"W | I17: Rua Campos Sales, Nova Esperança | J17: 1000 | K17: 2500 | L17: 4 | M17: 6 | N17: 00 | O17: 00 | P17: 6 | Q17: 00 | R17: 00 | S17: 00 | T17: 00 | U17: 00 | V17: 00 | W17: 00 | X17: 00 | Y17: 00 | Z17: 00 | AA17: 00 | AB17: 1 | AC17: 00 | AD17: 00 | AE17: 00 | AF17: 1 | AG17: 00 | AH17: 00 | AI17: 00 | AJ17: 00 | AK17: 00 | AL17: 00 | AM17: 00 | AN17: 00 | AO17: 00 | AP17: 00 | AQ17: 00
A18: 45476.406 | B18: pdfimahumaita@gmail.com | C18: Humaitá | D18: 45458 | E18: 0.70833333 | F18: INCÊNDIO FLORESTAL | G18: 3 | H18: -7⁰29'34,58423"S-63⁰1'33,87976"W19⁰N | I18: RUA: PORTOBRÁS, N⁰ 550 (BAIRRO: SÃO DOMINGOS SÁVIO) | J18: 600 | K18: 2000 | L18: 04 | M18: 06 | N18: 00 | O18: 00 | P18: 20 | Q18: 00 | R18: 00 | S18: 00 | T18: 00 | U18: 00 | V18: 00 | W18: 00 | X18: 00 | Y18: 00 | Z18: 00 | AA18: 00 | AB18: 01 | AC18: 00 | AD18: 00 | AE18: 00 | AF18: 00 | AG18: 00 | AH18: 00 | AI18: 00 | AJ18: 00 | AK18: 00 | AL18: 00 | AM18: 00 | AN18: 00 | AO18: 00 | AP18: 00 | AQ18: 00
A19: 45476.424 | B19: pdfimahumaita@gmail.com | C19: Humaitá | D19: 45458 | E19: 0.81875 | F19: INCÊNDIO FLORESTAL | G19: 3 | H19: -7⁰30'25,40381"S-63⁰2'32,20955"W248⁰W | I19: RUA: CAMPOS SALES, N⁰ 2384 (NOVA HUMAITÁ) | J19: 500 | K19: 400 | L19: 04 | M19: 06 | N19: 00 | O19: 00 | P19: 00 | Q19: 00 | R19: 00 | S19: 00 | T19: 00 | U19: 00 | V19: 00 | W19: 00 | X19: 00 | Y19: 00 | Z19: 00 | AA19: 00 | AB19: 00 | AC19: 00 | AD19: 00 | AE19: 00 | AF19: 01 | AG19: 00 | AH19: 00 | AI19: 00 | AJ19: 00 | AK19: 00 | AL19: 00 | AM19: 00 | AN19: 00 | AO19: 00 | AP19: 00 | AQ19: 00
A20: 45476.432 | B20: pdfimahumaita@gmail.com | C20: Humaitá | D20: 45458 | E20: 0.79861111 | F20: INCÊNDIO FLORESTAL | G20: 10 | H20: -7⁰30'25,38253"S-63⁰2'21408"W280⁰W | I20: RUA: CAMPOS SALES (BAIRRO: NOVA ESPERANÇA) | J20: 1000 | K20: 2000 | L20: 04 | M20: 06 | N20: 00 | O20: 00 | P20: 00 | Q20: 00 | R20: 00 | S20: 00 | T20: 00 | U20: 00 | V20: 00 | W20: 00 | X20: 00 | Y20: 00 | Z20: 00 | AA20: 00 | AB20: 01 | AC20: 00 | AD20: 00 | AE20: 00 | AF20: 00 | AG20: 00 | AH20: 00 | AI20: 00 | AJ20: 00 | AK20: 00 | AL20: 00 | AM20: 00 | AN20: 00 | AO20: 00 | AP20: 00 | AQ20: 00
A21: 45475.639 | B21: joaofelipe292@gmail.com | C21: Boca do Acre | D21: 45459 | E21: 0.66666667 | F21: INCÊNDIO FLORESTAL | G21: 26 | H21: 8.77711604S 67.33723269W | I21: loteamento jardim modelo, bairro São Cristóvão | J21: 70000 | K21: 3000 | P21: 04
A22: 45475.794 | B22: pgarciasbm@gmail.com | C22: Humaitá | D22: 45459 | E22: 0.62361111 | F22: INCÊNDIO FLORESTAL | G22: 3 | H22: -7.52536"S,-63.04117"W | I22: Rua Bom Conselho, conjunto Habitacional Uruapiara | J22: 300 | K22: 2500 | L22: 4 | M22: 2 | N22: 00 | O22: 00 | P22: 2 | Q22: 00 | R22: 00 | S22: 00 | T22: 00 | U22: 00 | V22: 00 | W22: 00 | X22: 00 | Y22: 00 | Z22: 00 | AA22: 00 | AB22: 1 | AC22: 00 | AD22: 00 | AE22: 00 | AF22: 00 | AG22: 00 | AH22: 00 | AI22: 00 | AJ22: 00 | AK22: 00 | AL22: 00 | AM22: 00 | AN22: 00 | AO22: 00 | AP22: 00 | AQ22: 00
A23: 45475.69 | B23: bmpaulolopes@gmail.com | C23: Manicoré | D23: 45460 | E23: 0.50486111 | F23: INCÊNDIO FLORESTAL | G23: 15 | I23: Campo do Cruzeiro - Estrada do Aeroporto - Bairro Laura Vicuna | J23: 2275 | K23: 600 | L23: 1 | M23: 0 | N23: 0 | O23: 0 | P23: 3 | Q23: 0 | R23: 0 | S23: 4 | T23: 0 | U23: 0 | V23: 0 | W23: 0 | X23: 0 | Y23: 0 | Z23: 0 | AA23: 0 | AB23: 0 | AC23: 0 | AD23: 0 | AE23: 0 | AF23: 1 | AG23: 0 | AH23: 0 | AI23: 0 | AJ23: 0 | AK23: 0 | AL23: 0 | AM23: 0 | AN23: 0 | AO23: 0 | AP23: 0 | AQ23: 0
A24: 45475.706 | B24: reneltonbatalha123@gmail.com | C24: Apuí | D24: 45460 | E24: 0.76736111 | F24: INCÊNDIO FLORESTAL | G24: 6 | I24: Bairro Cachoeirinha ao lado da UEA | J24: 700 | K24: 300 | L24: 0 | M24: 0 | N24: 0 | O24: 0 | P24: 04 | Q24: 0 | R24: 0 | S24: 0 | T24: 0 | U24: 0 | V24: 0 | W24: 0 | X24: 0 | Y24: 0 | Z24: 0 | AA24: 0 | AB24: 0 | AC24: 0 | AD24: 0 | AE24: 0 | AF24: 01 | AG24: 0 | AH24: 0 | AI24: 0 | AJ24: 0 | AK24: 0 | AL24: 0 | AM24: 0 | AN24: 0 | AO24: 0 | AP24: 0 | AQ24: 0
A25: 45475.799 | B25: pgarciasbm@gmail.com | C25: Humaitá | D25: 45460 | E25: 0.020138889 | F25: INCÊNDIO FLORESTAL | G25: 18 | H25: -7.52187"S,-63.03832 | I25: Br 230, 1 | J25: 2000 | K25: 2000 | L25: 00 | M25: 2 | N25: 00 | O25: 00 | P25: 2 | Q25: 00 | R25: 00 | S25: 00 | T25: 00 | U25: 00 | V25: 00 | W25: 00 | X25: 00 | Y25: 00 | Z25: 00 | AA25: 00 | AB25: 1 | AC25: 00 | AD25: 00 | AE25: 00 | AF25: 00 | AG25: 00 | AH25: 00 | AI25: 00 | AJ25: 00 | AK25: 00 | AL25: 00 | AM25: 00 | AN25: 00 | AO25: 00 | AP25: 00 | AQ25: 00
A26: 45475.711 | B26: reneltonbatalha123@gmail.com | C26: Apuí | D26: 45461 | E26: 0.52430556 | F26: INCÊNDIO FLORESTAL | G26: 7 | I26: BR 230, KM3 | J26: 1200 | K26: 600 | L26: 0 | M26: 0 | N26: 0 | O26: 0 | P26: 03 | Q26: 0 | R26: 0 | S26: 0 | T26: 0 | U26: 0 | V26: 0 | W26: 0 | X26: 0 | Y26: 0 | Z26: 0 | AA26: 0 | AB26: 0 | AC26: 0 | AD26: 0 | AE26: 0 | AF26: 01 | AG26: 0 | AH26: 0 | AI26: 0 | AJ26: 0 | AK26: 0 | AL26: 0 | AM26: 0 | AN26: 0 | AO26: 0 | AP26: 0 | AQ26: 0
A27: 45475.715 | B27: reneltonbatalha123@gmail.com | C27: Apuí | D27: 45462 | E27: 0.78472222 | F27: INCÊNDIO FLORESTAL | G27: 9 | I27: Vicinal Coruja | J27: 3000 | K27: 200 | L27: 0 | M27: 0 | N27: 0 | O27: 0 | P27: 04 | Q27: 04 | R27: 0 | S27: 0 | T27: 0 | U27: 0 | V27: 0 | W27: 0 | X27: 0 | Y27: 0 | Z27: 0 | AA27: 0 | AB27: 0 | AC27: 0 | AD27: 0 | AE27: 0 | AF27: 01 | AG27: 0 | AH27: 0 | AI27: 0 | AJ27: 0 | AK27: 0 | AL27: 01 | AM27: 0 | AN27: 0 | AO27: 0 | AP27: 0 | AQ27: 0
A28: 45475.813 | B28: pgarciasbm@gmail.com | C28: Humaitá | D28: 45462 | E28: 0.90625 | F28: INCÊNDIO FLORESTAL | G28: 6 | H28: -7.50576"S,-63.03741"W | I28: Rua Dom José, Nova Esperança | J28: 400 | K28: 500 | L28: 00 | M28: 2 | N28: 00 | O28: 00 | P28: 2 | Q28: 00 | R28: 00 | S28: 00 | T28: 00 | U28: 00 | V28: 00 | W28: 00 | X28: 00 | Y28: 00 | Z28: 09 | AA28: 00 | AB28: 1 | AC28: 00 | AD28: 00 | AE28: 00 | AF28: 00 | AG28: 00 | AH28: 00 | AI28: 00 | AJ28: 00 | AK28: 00 | AL28: 00 | AM28: 00 | AN28: 00 | AO28: 00 | AP28: 00 | AQ28: 00
A29: 45475.625 | B29: wagnneerrd@gmail.com | C29: Humaitá | D29: 45463 | E29: 0.44305556 | F29: INCÊNDIO FLORESTAL | G29: 22 | I29: Alto Crato | J29: 20000 | K29: 20000 | L29: 3 | P29: 6 | Q29: 12 | AA29: 1
A30: 45475.628 | B30: wagnneerrd@gmail.com | C30: Humaitá | D30: 45463 | E30: 0.50069444 | F30: INCÊNDIO FLORESTAL | G30: 12 | I30: Rua Dom José. Bairro Nova Humaitá. | J30: 2000 | K30: 6000 | P30: 6 | Q30: 12 | AA30: 1
A31: 45483.676 | B31: salacbmam@gmail.com | C31: Novo Airão | D31: 45463 | E31: 0.8125 | F31: INCÊNDIO FLORESTAL | G31: 5 | I31: Rua Almerinda Malaquias, Caminho das Índias, 241 | J31: 400 | K31: 10000 | O31: 3 | R31: 3
A32: 45468.656 | B32: avs.vanessaalves@gmail.com | C32: Autazes | D32: 45464 | E32: 0.64236111 | F32: INCÊNDIO FLORESTAL | G32: 4 | H32: -3°35'29,592"S -59°8'15,522"W | I32: Estrada da Fábrica de Gelo Bairro Mutirão | J32: 600 | K32: 2000 | L32: 00 | M32: 03 | N32: 00 | O32: 00 | P32: 08 | Q32: 00 | R32: 00 | S32: 01 | T32: 00 | U32: 00 | V32: 00 | W32: 00 | X32: 00 | Y32: 00 | Z32: 00 | AA32: 00 | AB32: 00 | AC32: 00 | AD32: 00 | AE32: 00 | AF32: 00 | AG32: 00 | AH32: 00 | AI32: 00 | AJ32: 00 | AK32: 00 | AL32: 00 | AM32: 01 | AN32: 00 | AO32: 00 | AP32: 00 | AQ32: 00
A33: 45475.6 | B33: haninhalopes02@gmail.com | C33: Novo Aripuanã | D33: 45464 | E33: 0.45833333 | F33: INCÊNDIO FLORESTAL | G33: 3 | I33: Rua Rogério Braga, s/n bairro Tucumã | K33: 300 | L33: 6 | M33: 2 | N33: 0 | O33: 0 | P33: 6 | Q33: 0 | R33: 0 | S33: 0 | T33: 0 | U33: 0 | V33: 0 | W33: 0 | X33: 0 | Y33: 0 | Z33: 0 | AA33: 0 | AB33: 0 | AC33: 0 | AD33: 0 | AE33: 0 | AF33: 1 | AG33: 0 | AH33: 0 | AI33: 0 | AJ33: 0 | AK33: 0 | AL33: 0 | AM33: 0 | AN33: 0 | AO33: 0 | AP33: 0 | AQ33: 0
A34: 45475.94 | B34: farm.edumaga@gmail.com | C34: Manaquiri | D34: 45464 | E34: 0.69444444 | F34: INCÊNDIO FLORESTAL | G34: 3 | H34: -3.2636, 60.2739 | J34: 100 | K34: 30 | L34: 02 | M34: 03 | P34: 08 | S34: 09 | AF34: 01
A35: 45475.943 | B35: farm.edumaga@gmail.com | C35: Manaquiri | D35: 45464 | E35: 0.76736111 | F35: INCÊNDIO FLORESTAL | G35: 1 | H35: -3.2615, -60.2711 | J35: 10 | K35: 0 | L35: 02 | M35: 03 | P35: 08 | S35: 09 | AF35: 01
A36: 45476.363 | B36: pdfimahumaita@gmail.com | C36: Humaitá | D36: 45464 | E36: 0.96805556 | F36: INCÊNDIO FLORESTAL | G36: 5 | H36: -7⁰31'5,27912"S-63⁰,02929"W5⁰N | I36: BR-230, KM-02 (BAIRRO: SÃO PEDRO) | J36: 800 | K36: 1000 | L36: 04 | M36: 06 | N36: 00 | O36: 00 | P36: 20 | Q36: 00 | R36: 00 | S36: 00 | T36: 00 | U36: 00 | V36: 00 | W36: 00 | X36: 00 | Y36: 00 | Z36: 00 | AA36: 01 | AB36: 00 | AC36: 00 | AD36: 00 | AE36: 00 | AF36: 00 | AG36: 00 | AH36: 00 | AI36: 00 | AJ36: 00 | AK36: 00 | AL36: 00 | AM36: 00 | AN36: 00 | AO36: 00 | AP36: 00 | AQ36: 00
A37: 45476.379 | B37: pdfimahumaita@gmail.com | C37: Humaitá | D37: 45464 | E37: 0.77430556 | F37: INCÊNDIO FLORESTAL | G37: 3 | H37: -7⁰34'13,69617"S-63⁰4'21,85893"W | I37: BR-319, KM-11 (ÁREA RURAL) | J37: 1700 | K37: 4000 | L37: 04 | M37: 06 | N37: 00 | O37: 00 | P37: 20 | Q37: 00 | R37: 00 | S37: 00 | T37: 00 | U37: 00 | V37: 00 | W37: 00 | X37: 00 | Y37: 00 | Z37: 00 | AA37: 01 | AB37: 00 | AC37: 00 | AD37: 00 | AE37: 00 | AF37: 00 | AG37: 00 | AH37: 00 | AI37: 00 | AJ37: 00 | AK37: 00 | AL37: 00 | AM37: 00 | AN37: 00 | AO37: 00 | AP37: 00 | AQ37: 00
A38: 45468.632 | B38: meirebm07@gmail.com | C38: Autazes | D38: 45465 | E38: 0.40972222 | F38: INCÊNDIO FLORESTAL | G38: 1 | H38: -3.585751, -59.133087 | I38: Rua Presidente Kennedy, n. 06, Bairro Multirão | J38: 0 | K38: 0 | L38: 2 | M38: 4 | N38: 0 | O38: 0 | P38: 8 | Q38: 0 | R38: 0 | S38: 0 | T38: 0 | U38: 0 | V38: 0 | W38: 0 | X38: 0 | Y38: 0 | Z38: 0 | AA38: 0 | AB38: 0 | AC38: 0 | AD38: 0 | AE38: 0 | AF38: 0 | AG38: 0 | AH38: 0 | AI38: 0 | AJ38: 0 | AK38: 0 | AL38: 0 | AM38: 1 | AN38: 0 | AO38: 0 | AP38: 0 | AQ38: 0
A39: 45468.637 | B39: meirebm07@gmail.com | C39: Autazes | D39: 45465 | E39: 0.63888889 | F39: INCÊNDIO FLORESTAL | G39: 1 | H39: -3.5755850, -59.1129800 | I39: Lago do Gomo, Sítio Aquários, próx UBS Salvina Pontes | J39: 2100 | K39: 40 | L39: 02 | M39: 04 | N39: 0 | O39: 00 | P39: 08 | Q39: 00 | R39: 04 | S39: 00 | T39: 00 | U39: 00 | V39: 00 | W39: 00 | X39: 00 | Y39: 00 | Z39: 00 | AA39: 00 | AB39: 00 | AC39: 00 | AD39: 00 | AE39: 00 | AF39: 00 | AG39: 00 | AH39: 00 | AI39: 00 | AJ39: 00 | AK39: 00 | AL39: 00 | AM39: 01 | AN39: 00 | AO39: 00 | AP39: 00 | AQ39: 00
A40: 45468.64 | B40: meirebm07@gmail.com | C40: Autazes | D40: 45465 | E40: 0.75 | F40: INCÊNDIO FLORESTAL | G40: 1 | H40: -3.613791, -59.134687 | I40: Estrada do Rosarinho, s/n, próx. Casa da Cultura | J40: 0 | K40: 0 | L40: 02 | M40: 04 | N40: 00 | O40: 00 | P40: 08 | Q40: 00 | R40: 00 | S40: 00 | T40: 00 | U40: 00 | V40: 00 | W40: 00 | X40: 00 | Y40: 00 | Z40: 00 | AA40: 00 | AB40: 00 | AC40: 00 | AD40: 00 | AE40: 00 | AF40: 00 | AG40: 00 | AH40: 00 | AI40: 00 | AJ40: 00 | AK40: 00 | AL40: 00 | AM40: 01 | AN40: 00 | AO40: 00 | AP40: 00 | AQ40: 00
...

Sheet Página4
A1: Macrogrupo | B1: Naturezas | C1: Ano | D1: Mês | E1: Data Atendimento | F1: Data Ocorrência | G1: Data Envio Despacho | H1: Data Empenho Equipe | I1: Narrativa | J1: Atividades | K1: Usuario Finalizador
A2: Incêndio em edificação | B2: Incêndio em residência | C2: 2023 | D2: Jan | E2: 44927 | G2: 44927 | H2: 44927 | I2: 1º BI, POSTO ZUMBI, VIATURA ABT-30, SOB O COMANDO DO SARGENTO BM SILVA, CONTROLARAM INCÊNDIO EM INSTÂNCIA DE ALVENARIA SOLICITANTE: FABIANA FERREIRA, CONTATO: 99625-8128. PROPRIETÁRIO: ARNALDO FRANÇA DE MATOS JÚNIOR. RG 279465- 8, CPF 023 744 832 74 BAIRRO: MAUAZINHO, RUA S. FRANCISCO, N 50. INCENDIO EM 2 KITNETES MEDINDO +- 3X5. PREJUÍZO MATERIAL: 01 GELADEIRA, 01 TV , 01 CAMA ,01COLCHÃ, FORRO PVC, REBOCO DA PAREDE, ESPELHO. NO COMBATE E RESCALDO FORAM USADOS 2MIL LITROS DE ÁGUA. NA RUA: SÃO FRANCISCO N56 MAUAZINHO, PRÓXIMO AO CAMPO DO VERMELHÃO SOLICITANTE: FABIANA FERREIRA CONTATO: 99625-8128 | K2: Waldira Marinho Lima Oliveira
A3: Incêndio em edificação | B3: Incêndio em residência | C3: 2023 | D3: Jan | E3: 44927 | G3: 44927 | H3: 44927 | I3: COMANDANTE DE SOCORRO, VIATURA AR-55'1º BI, POSTO CIS GRANDE CISCULAR, VIATURA ABT-25, SOB O COMANDO DO SARGENTO BM ARIULDO, CONTROLARAM INCÊNDIO EM RESIDENCIA DE ALVENARIA, HOUVE QUEIMA DE: 1 CAMA DE SOLTEIRO, FORRO PVC 15M², UM GUARDA ROUPA 4 PORTAS MDF, E DIVERSOS PEÇAS DE ROUPAS, QUEIMA PARCIAL DE DOIS QUARTOS DA CASA, PROPRIETÁRIA SENHORA ALCINDA FERREIRA DA SILVA, NO COMBATE E RESCALDO FORAM USADOS 2,000 LITROS DE ÁGUA. PRINCÍPIO DE INC¿NDIO EM RESIDÊNCIA DE ALVENARIA, NA RUA PADRE CÍCERO N196 CIDADE DE DEUS, PRÓXIMO AO SALMO 91 SOLICITANTE: KELVE CONTATO: 993860957 | K3: Waldira Marinho Lima Oliveira
A4: Incêndio em edificação | B4: Incêndio em residência | C4: 2023 | D4: Jan | E4: 44927 | G4: 44927 | I4: PRINCÍPIO DE INCÊNDIO EM CASA DE ALVENARIA NA RUA IRMÃ ELIZABETH BAYMA 337 NOVA CIDADE SOLICITANTE: WESLEY CONTATO: 99438 -8687 | K4: Waldira Marinho Lima Oliveira
A5: Outras ocorrências | B5: Atendimento pré-hospitalar transporte de paciente | C5: 2023 | D5: Jan | E5: 44927 | G5: 44927 | H5: 44927 | I5: ATENDIMENTO PRÉ HOSPITALAR TRANSPORTE DE PACIENTE PARA O HOSPITAL E PRONTO SOCORRO DR. JOÃO LÚCIO PEREIRA MACHADO AV. COSME E FERREIRA - COROADO PACIENTE: NEILON COSME ALVVES CONTATO: 993639798 GREM POSTO ZUMBI, VIATURA UR-19, PLANO DE OPERAÇÕES Nº 101-CBC/2022 OPERAÇÃO REVEILLON SHOPÍNG FELIPE DAOU, SEGUNDO TURNO REALIZARAM ATENDIMENTO PRÉ HOSPÍTALAR: TIPO DA OCORRÊNCIA:COLISÃO MOTO X MOTO, LOCAL DA OCORRÊNCIA: EM FRENTE AO SHOPPING PHILLIP DAOU, UR-19 GU SV, 1°TEN LEONARDO CORRÊA, 1°TEN MARCOS ALEXANDRE, 3°SGT HELINALDO, SITUAÇÃO DA , CORRÊNCIA. UR 19 ACIONADA PELA PM NA PREVENÇÃO DO RÉVEILLON NO ESTACIONAMENTO DO SHOPPING PHILLIP DAOU PARA ATENDIMENTO DE VÍTIMA DE COLISÃO MOTO X MOTO. AÇÃO DOS BOMBEIROS: À CHEGADA NO LOCAL DA OCORRÊNCIA, VÍTIMA DEAMBULANDO, COM SINAIS DE EMBRIAGUEZ, CONSCIENTE, ORIENTADO, COM TRAUMA CORTO CONTUDO EM FACE, NA REGIÃO DE SUPERCÍLIO DIREITO, NASAL E MAXILAS. REALIZADA IMOBILIZAÇÃO PADRÃO, XABCDE, ACESSO VENOSO PERIFERICO E TRANSPORTE AO HPS JOÃO LÚCIO. AVALIAÇÃO PRIMARIA, XABCDE. IMOBILIZAÇÃO PADRÃO EM PRANCHA LONGA. AVALIAÇÃO SECUNDÁRIA, SSVV, PA: 160X90, SPO2: 98% EM AR AMBIENTE, FC: 115, FR: 19, ENCAMINHAMENTO, ENCAMINHADO AO HPS JOÃO LÚCIO, SETOR DE POLITRAUMA. RECEBIDO PELO MÉDICO JULIANA OZORES CRM AM 5261. DADOS DA VÍTIMA: NOME: NEILON COSME ALVES, 35 ANOS, RG:4471171, ENDEREÇO: RUA MONTE VERDE N95, BAIRRO GILBERTO MESTRINHO, TELEFONE: 99363-9798 | K5: Waldira Marinho Lima Oliveira
A6: Outras ocorrências | B6: Atendimento pré-hospitalar transporte de paciente | C6: 2023 | D6: Jan | E6: 44927 | G6: 44927 | H6: 44927 | I6: ATENDIMENTO PRÉ HOSPITALAR TRANSPORTE DE PACIENTE PARA O HP DR. JOÃO LÚCIO PEREIRA MACHADO - AVENIDA COSME E FERREIRA COROADO PACIENTE: MARCIO DOS SANTOS SOUZA 36 ANOS GREM POSTO ZUMBI, VIATURA UR-19, PLANO DE OPERAÇÕES Nº 101-CBC/2022 OPERAÇÃO REVEILLON SHOPÍNG FELIPE DAOU, SEGUNDO TURNO REALIZARAM ATENDIMENTO PRÉ HOSPÍTALAR: TIPO DA OCORRÊNCIA: QUEDA DA PRÓPRIA ALTURA COM TCE, LOCAL DA OCORRÊNCIA: ESTACIONAMENTO DO SHOPPING PHILLIP DAOU, UR-19 GU SV, 1°TEN LEONARDO CORRÊA, 1°TEN MARCOS ALEXANDRE, _3°SGT HELINALDO, SITUAÇÃO DA OCORRÊNCIA. UR 19 ACIONADA PELA EQUIPE DE APH DA PREVENÇÃO PARA ATENDIMENTO DE VÍTIMA DE QUEDA DA PRÓPRIA ALTURA COM PERDA DE CONSCIÊNCIA. AÇÃO DOS BOMBEIROS: À CHEGADA NO LOCAL DA OCORRÊNCIA, VÍTIMA IMOBILIZADA EM PRANCHA LONGA, COM TRAUMA CORTO CONTUSO EM REGIÃO PARIETAL ESQUERDA E FRONTAL COM SANGRAMENTO ATIVO. VÍTIMA APRESENTANDO CONVULSÕES DURANTE O TRANSPORTE. REFERE RETROVIROSE. REALIZADA AVALIAÇÃO PRIMÁRIA E SECUNDÁRIA, ACESSO VENOSO PERIFERICO E TRANSPORTE AO HPS JOÃO LÚCIO.AVALIAÇÃO PRIMARIA XABCDE. IMOBILIZAÇÃO PADRÃO EM PRANCHA LONGA, OXIGENOTERAPIA COM MÁSCARA COM RESERVATÓRIO 10L/MIN, ACESSO VENOSO PERIFERICO. AVALIAÇÃO SECUNDÁRIA, SSVV, PA: 120X80, SPO2: 98% EM MÁSCARA COM RESERVATÓRIO 10L/MIN,FC: 120, FR: 22,ENCAMINHADO AO HPS JOÃO LÚCIO, SETOR DE POLITRAUMA. RECEBIDO PELA MÉDICA RANNA AM 5170, DADOS DA VÍTIMA: NOME: MARCIO DOS SANTOS SOUZ, 36 ANOS, RG: 2321829-9, ENDEREÇO: RUA CRAVINHO N 450, BAIRRO: JORGE TEIXEIRA 4. ETAPA, TELEFONE: NÃO INFORMADO. | K6: Waldira Marinho Lima Oliveira
A7: Outras ocorrências | B7: Prevenção - outros | C7: 2023 | D7: Jan | E7: 44927 | G7: 44927 | H7: 44927 | I7: SEG DOS POSTOS CBMAM. CB DIRLEY SOUZA 1026 06:00 18:00 12:00 POSTO PONTA NEGRA 233/CIA CG/2024 REFORÇO DE GUARNIÇÃO CB CLEUTON 1037 06:00 18:00 12:00 POSTO PONTA NEGRA 233/CIA CG/2024 REFORÇO DE GUARNIÇÃO CB TOURINHO 1095 06:00 18:00 12:00 POSTO PONTA NEGRA 233/CIA CG/2024 REFORÇO DE GUARNIÇÃO CB WANDER 1255 06:00 18:00 12:00 POSTO PONTA NEGRA 233/CIA CG/2024 REFORÇO DE GUARNIÇÃO SGT RICARDO GOMES 1627 06:00 18:00 12:00 POSTO PONTA NEGRA 075/DG-PGGM/2024 REFORÇO DE GUARNIÇÃO SGT FIGUEIRA 1673 06:00 18:00 12:00 POSTO PONTA NEGRA 075/DG-PGGM/2024 REFORÇO DE GUARNIÇÃO ST ESMERALDO 631 06:00 18:00 12:00 POSTO PONTA NEGRA 964/BBE/2024 REFORÇO DE GUARNIÇÃO CB HENRIQUE LEMOS 1064 06:00 18:00 12:00 POSTO PONTA NEGRA 964/BBE/2024 REFORÇO DE GUARNIÇÃO CB BRUNA 1182 06:00 18:00 12:00 POSTO PONTA NEGRA 964/BBE/2024 REFORÇO DE GUARNIÇÃO CB VICTOR 1036 07:30 19:30 12:00 POSTO RODOVIARIA 965/BBE/2022 REFORÇO DE GUARNIÇÃO ST COSTA E SILVA 378 07:30 19:30 12:00 SCI-AEROPORTO 001/SCI/2024 REFORÇO DE GUARNIÇÃO CB NOGUEIRA 1091 07:30 19:30 12:00 SCI-AEROPORTO 001/SCI/2024 REFORÇO DE GUARNIÇÃO CB RAFAELE 1191 07:30 19:30 12:00 SCI-AEROPORTO 001/SCI/2024 REFORÇO DE GUARNIÇÃO SGT A. SOUSA 1591 08:00 20:00 12:00 POSTO ZUMBI 859/GREM/2024 REFORÇO DE GUARNIÇÃO SGT JEFERSON ARAUJO 1533 13:00 23:00 10:00 TEATRO AMAZ. 108/CBC/2022 POSSE GOVERNADOR SGT ADEILSON 1844 13:00 23:00 10:00 TEATRO AMAZ. 108/CBC/2022 POSSE GOVERNADOR CB PASSOS 1033 14:00 23:00 09:00 TEATRO AMAZ. 126/COBOM/2024 POSSE E JANTAR DO GOVERNADOR CB PIMENTA 1167 13:00 20:00 07:00 TEATRO AMAZ. 967/BBE POSSE E JANTAR DO GOVERNADOR SGT RAINNIER NORONHA 695 14:00 22:00 08:00 TEATRO AMAZ. 407/BIFMA PCI SGT S. ROCHA 771 14:00 22:00 08:00 TEATRO AMAZ. 407/BIFMA PCI TEN MOTA 532 14:00 22:00 08:00 TEATRO AMAZ. 183/DAT POSSE E JANTAR DO GOVERNADOR ST POLARI 528 14:00 22:00 08:00 TEATRO AMAZ. 183/DAT POSSE E JANTAR DO GOVERNADOR ST LUCIO 539 14:00 22:00 08:00 TEATRO AMAZ. 183/DAT POSSE E JANTAR DO GOVERNADOR SGT GOES 594 14:00 22:00 08:00 TEATRO AMAZ. 183/DAT POSSE E JANTAR DO GOVERNADOR SGT F. PAULO 735 14:00 22:00 08:00 TEATRO AMAZ. 183/DAT POSSE E JANTAR DO GOVERNADOR SGT GUTEMBERGUE 741 14:00 22:00 08:00 TEATRO AMAZ. 183/DAT POSSE E JANTAR DO GOVERNADOR CB GETLEN 1025 14:00 22:00 08:00 TEATRO AMAZ. 183/DAT POSSE E JANTAR DO GOVERNADOR TEN ALAIDE NEVES 1328 15:00 22:00 07:00 TEATRO AMAZ. 153/DS POSSE E JANTAR DO GOVERNADOR TEN LOUREIRO 1335 15:00 22:00 07:00 TEATRO AMAZ. 153/DS POSSE E JANTAR DO GOVERNADOR TEN MARINALDO 1407 15:00 22:00 07:00 TEATRO AMAZ. 153/DS POSSE E JANTAR DO GOVERNADOR TEN MARCELO MORAES 1476 15:00 22:00 07:00 TEATRO AMAZ. 153/DS POSSE E JANTAR DO GOVERNADOR TEN ROGERIO XIMENES 1355 15:00 22:00 07:00 TEATRO AMAZ. 153/DS POSSE E JANTAR DO GOVERNADOR TEN ÉRICA 1522 15:00 22:00 07:00 TEATRO AMAZ. 153/DS POSSE E JANTAR DO GOVERNADOR TEN PATENA 1401 15:00 22:00 07:00 TEATRO AMAZ. 153/DS POSSE E JANTAR DO GOVERNADOR TEN DO VALE 1409 15:00 22:00 07:00 TEATRO AMAZ. 153/DS POSSE E JANTAR DO GOVERNADOR TEN LISSA 1370 15:00 22:00 07:00 TEATRO AMAZ. 153/DS POSSE E JANTAR DO GOVERNADOR TEN INDAYAH 1438 15:00 22:00 07:00 TEATRO AMAZ. 153/DS POSSE E JANTAR DO GOVERNADOR TEN LUANNY GOMES 1481 15:00 22:00 07:00 TEATRO AMAZ. 153/DS POSSE E JANTAR DO GOVERNADOR TEN SILVIA CRISTINA 1362 15:00 22:00 07:00 TEATRO AMAZ. 153/DS POSSE E JANTAR DO GOVERNADOR | J7: TEN THALYADE 1430 15:00 22:00 07:00 TEATRO AMAZ. 153/DS POSSE E JANTAR DO GOVERNADOR TEN CARLOS ANTONIO 1436 15:00 22:00 07:00 TEATRO AMAZ. 153/DS POSSE E JANTAR DO GOVERNADOR TEN PEDRO SANTOS 1431 15:00 22:00 07:00 TEATRO AMAZ. 153/DS POSSE E JANTAR DO GOVERNADOR TEN SERGIO CARVALHO 1826 15:00 22:00 07:00 TEATRO AMAZ. 153/DS POSSE E JANTAR DO GOVERNADOR SGT LIDIANE 1638 15:00 22:00 07:00 TEATRO AMAZ. 153/DS POSSE E JANTAR DO GOVERNADOR SGT JOVELINA 1671 15:00 22:00 07:00 TEATRO AMAZ. 153/DS POSSE E JANTAR DO GOVERNADOR CB NEIRES 1798 15:00 22:00 07:00 TEATRO AMAZ. 153/DS POSSE E JANTAR DO GOVERNADOR CB BRUNO QUEZADA 1802 15:00 22:00 07:00 TEATRO AMAZ. 153/DS POSSE E JANTAR DO GOVERNADOR CB LADISLAU 1778 15:00 22:00 07:00 TEATRO AMAZ. 153/DS POSSE E JANTAR DO GOVERNADOR TEN EVELYN 1426 15:00 22:00 07:00 TEATRO AMAZ. 153/DS POSSE E JANTAR DO GOVERNADOR TEN JOQUEBEDE 1394 15:00 22:00 07:00 TEATRO AMAZ. 153/DS POSSE E JANTAR DO GOVERNADOR SGT F. MOTA 1333 15:00 22:00 07:00 TEATRO AMAZ. 153/DS POSSE E JANTAR DO GOVERNADOR SGT SÁVIA 1700 15:00 22:00 07:00 TEATRO AMAZ. 153/DS POSSE E JANTAR DO GOVERNADOR SGT CAMILA DIAS 1595 15:00 22:00 07:00 TEATRO AMAZ. 153/DS POSSE E JANTAR DO GOVERNADOR SGT SIMPLICIO 1691 15:00 22:00 07:00 TEATRO AMAZ. 153/DS POSSE E JANTAR DO GOVERNADOR ST ARTUR 635 14:00 22:00 08:00 TEATRO AMAZ. 238/CIACG POSSE E JANTAR DO GOVERNADOR CB DORIAN 1109 14:00 22:00 08:00 TEATRO AMAZ. 962/BBE POSSE E JANTAR DO GOVERNADOR CB ELIELSON 1159 18:00 06:00 12:00 QCG 235/CIA CG/2022 SENTINELA ARMADA SERVIÇO DO DIA 01.01.2024 / 1º TURNO CMT DE SOCORRO: 2º TEN BM VALÉRIO CONTROLADOR COBOM: 1º TEN BM RICARDO ------------------------------------------------------------------------------------------------------------------------------------------------------------- CB RONALDO 1153 19:30 07:30 12:00 PB-RODOVIÁRIA 965/BBE/2022 REFORÇO DE GUARNIÇÃO ST VIEIRA PAIVA 375 19:30 07:30 12:00 SCI 002/SCI/2024 REFORÇO DE GUARNIÇÃO TEN MATOS 570 19:30 07:30 12:00 SCI 002/SCI/2024 REFORÇO DE GUARNIÇÃO CB MOREIRA JÚNIOR 1256 19:30 07:30 12:00 SCI 002/SCI/2024 REFORÇO DE GUARNIÇÃO CB LÉCIO 1093 20:00 08:00 12:00 DAT 181/DAT/2022 PERMANENCIA SGT ROBERTO PIMENTEL 1568 20:00 08:00 12:00 PONTA NEGRA 860/GREM/2022 REFORÇO DE GUARNIÇÃO SERVIÇO DO DIA 01.01.2024 / 2º TURNO CMT DE SOCORRO: 2º TEN BM VALÉRIO CONTROLADOR COBOM: 1º TEN BM R. LIRA | K7: Rozivaldo de Souza Lira
A8: Outras ocorrências | B8: Encontro de cadáver | C8: 2023 | D8: Jan | E8: 44927 | G8: 44927 | H8: 44927 | I8: Solicitante informa que acabaram de encontrar um cadáver esquartejado no local, pede-se apoio de vtr. | J8: A GUARNIÇÃO DA VIATURA 7307 DA 3º CICOM, AO COMANDO DO SARGENTO BRAGA, INFORMOU QUE FOI ENCONTRADO EM VIA PUBLICA UM CADARVER DO SEXO MASCULINO ESQUARTEJADO, SEGUNDO OS POLICIAIS, PRIMEIRAMENTE FOI ENCONTRADO SOMENTE O TRONCO DA VÍTIMA, MAIS ADIANTE TEM UM BUEIRO E OS POLICIAIS AVISTARAM UMA GRANDE MOVIMENTAÇÃO DE MOSCAS, AO AVERIGUAR, FORAM ENCONTRADOS AS DUAS PERNAS, OS DOIS BRAÇOS E A CABEÇA. FOI SOLICITADO APOIO DE UMA EQUIPE DO BOMBEIRO.NINGUEM CONHECE A VITIMA. VITIMA - SEXO MASCULINO APROXIMADAMENTE 25 ANOS VIATURAS DO ESTADO EMPENHADAS NESTA OCORRENCIA: 3º CICOM 47.0 VTR 7307 SGT BRAGA 14400 SGT JEMERSON 19167 SGT RUI DA SILVA 17933 HOMICIDO VTR 311 DELEGADO - RAFAEL AMANGUE INVESTIGADORES - ADRIANA ANDREI JERONIMO BOMBEIRO APT 31 COMANDANTE - CABO ROBSON CABO PIMENTEL CABO ALAN OLIVEIRA VTR 2008 PERICIA DA CRIMINALISTICA ALACIDE MOREIRA RICARDO CAMPOS IML 667 FAROL FRANCISCO ALVES AUXILIAR NECROPCIA RIBAMAR | K8: LUIZ RICARDO DE OLIVEIRA ALBUQUERQUE
A9: Outras ocorrências | B9: Prevenção em festas / eventos diversos | C9: 2023 | D9: Jan | E9: 44927 | G9: 44927 | H9: 44927 | I9: POSTO CENTRAL, VIATURA, ABT-31, UR-23, ABP-01, SOB O COMANDO DO CAPITÃO EDU COSTA, DESLOCARAM PARA CUMPRIR O.S 108/CBC/2022; EVENTO: POSSE DO GOVERNADOR; LOCAL: TEATRO AMAZONAS; HORÁRIO: 15:00 PRONTO. PLANO DE OPERAÇÕES Nº 108/CBC/2022; EVENTO: POSSE DO GOVERNADOR; LOCAL: TEATRO AMAZONAS; VIATURAS: ABT-29, ABT-31, UR-23, ABP-01 À COMANDO DO CAP BM EDU. HORÁRIO: 15:00 PRONTO. TÉRMINO DE PREVENÇÃO NO TEATRO AMAZONAS, AS VIATURAS DESLOCAM PARA O SEGUNDO PONTO DE PREVENÇÃO, NO CENTRO DE CONVENÇÕES VASCO VASQUES. TÉRMINO DE PREVENÇÃO, AS VIATURAS RETREM AOS SEUS POSTOS DE ORIGEM. SERVIÇO DO DIA 01.01.2024 / 2º TURNO CMT DE SOCORRO: 2º TEN BM VALÉRIO CONTROLADOR COBOM: 1º TEN BM R. LIRA | K9: Rozivaldo de Souza Lira
A10: Outras ocorrências | B10: Afogamento | C10: 2023 | D10: Jan | E10: 44927 | G10: 44927 | H10: 44927 | I10: AFOGAMENTO NA PRAIA DA PONTA NEGRA. EQUIPE DE SALVA VIDAS, GREM, UR-23, POSTO PONTA NEGRA, VITIMA APROXIMADAMENTE 30ANOS. SEM IDENTIFICAÇÃO E SEM DOCUMENTO. UM RAPAZ DISSE QUE CONHECIA ELE. MAS NAO SOUBE INFORMAR, ATUAÇÃO DOS BOMBEIROS, RETIRADA DO MEIO LÍQUIDO, PROCEDIMENTO DE REANIMAÇÃO CARDIO PULMONAR SEM EXITO, O CORPO FOI ENTREGUE A POLICIA CIVIL DELEGADO RAFAEL ALEMAND E INVESTIGADOR LUKEDISON, DHS VTR 311, IML VTR 667, RIBAMAR CARVALHO E FRANCISCO ALVES. | K10: LUIZ RICARDO DE OLIVEIRA ALBUQUERQUE
A11: Outras ocorrências | B11: Corte de algema / anel / outros | C11: 2023 | D11: Jan | E11: 44927 | G11: 44927 | H11: 44927 | I11: Ocorrencia de retirada de objeto circular de ferro do dedo anelar direito da mao de Ana Karen de Souza Santiago, 21 anos, RG 3227679-6. Tel. 99536-4404. Residente a rua Sant Petemberg N.07 bairro Nova cidade. A mesma estava acompanhada de seu esposo o senhor Morients Pereira Vieira, 22 anos, tel. 99349-7668. BBE, POSTO CENTRAL, VIATUAR ABT-29, RERALIZARAM RETIRADA DE OBJETO CIRCULAR DE FERRO DO DEDO ANELAR DIREITO DA MÃO DE: ANA KAREN DE SOUZA SANTIAGO, 21 ANOS, RG 3227679-6. TEL. 99536-4404. RESIDENTE A RUA SANT PETEMBERG N.07 BAIRRO NOVA CIDADE. A MESMA ESTAVA ACOMPANHADA DE SEU ESPOSO O SENHOR MORIENTS PEREIRA VIEIRA, 22 ANOS, TEL. 99349-7668. S.A. | K11: LUIZ RICARDO DE OLIVEIRA ALBUQUERQUE
A12: Outras ocorrências | B12: Encontro de cadáver | C12: 2023 | D12: Jan | E12: 44927 | G12: 44927 | I12: BBE, POSTO RODOVIÁRIA, VIATURA ABT-29, DESLOCOU PARA ENCONTRO DE CADÁVER EM APOIO A POLICIA MILITAR, EM ANDAMENTO... BBE; PB RODOVIÁRIA; VTR ABT-29 À COMANDO DO SGT BM VITAL. DESLOCA AO LOCAL SOLICITADO, ATENDE ROCORRÊNCIA DE RESGATE DE CADÁVER. LOCALIZAÇÃO E REMOÇÃO DE CADÁVER. SOLICITAÇÃO POR PARTE DA GUARNIÇÃO DA PMAM DO CIPCAES. LOCAL, ÁREA DE MATA FECHADA. AÇÃO DA GUARNIÇÃO CBMAM: RETIRADA DE UM CORPO EM ESTADO AVANÇADO DE DECONPOSIÇÃO, EM UMA COVA DE APROXIMADAMENTE 1m À 1.10m DE PROFUNDIDADE, UTILIZAÇÃO DE MATERIAL DE SAPA. NO LOCAL ACOMPANHANDO TODO SERVIÇO, O DELEGADO RAFAEL ALLEMAND, DA DELEGACIA DE HOMICIDIOS, INVESTIGADORES: LUKEDSON E ANDREI, NA VTR 311. EQUIPE DO IML VTR 741. FRANCISCO (MOTORISTA) SENHORES FRANCISCO E RIBAMAR AUXILIAR. PERÍCIA VTR 2005 PERITO: ALTAIDE E MOTORISTA RICARDO CAMPOS. EQUIPE PMAM: ROCAM VTR 9225 A COMANDO DO SGT PM W. BEZERRA, FAROL SD ROMULO, SD E. BRASIL AUXILIAR. EQUIPE DA CIPCAES VTR 9226, FAROL CB RICARDO MELO CH. SGT EMERSON E AUX. CB JAMISON, CADELA FIONA. CORPO ENTREGUE AOS CUIDADOS DO IML. A VTR ABT-29 RETRAIU AO PB DE ORIGEM. SERVIÇO DO DIA 01.01.2024 / 2º TURNO CMT DE SOCORRO: 2º TEN BM VALÉRIO CONTROLADOR COBOM: 1º TEN BM R. LIRA | J12: VTR 9226/CANIL AVERIGUAÇÃO DE ENCONTRO DE CADÁVER | K12: Rozivaldo de Souza Lira
A13: Outras ocorrências | B13: Desaparecimento de pessoa | C13: 2023 | D13: Jan | E13: 44927 | G13: 44927 | H13: 44927 | I13: BBE, PELOTÃO PONTA NEGRA, Walcinara da Silva barrocas tel.993992892 Filho: kaik Ruan da Silva de Souza 5 anos Ende: rua bacuri 38 Tarumã LOCAL DO DESAPARECIMENTO: Praia da ponta Negra BBE, PELOTÃO PONTA NEGRA, ENCONTRARAM A CRIANÇA: WALCINARA DA SILVA BARROCAS, 5 ANOS, FILHO: KAIK RUAN DA SILVA DE SOUZA, TEL.993992892, ENDEREÇO: RUA BACURI, Nº 38, BAIRRO TARUMÃ, A CRIANÇA ESTAVA CHORANDO ANDANDO SOZINHA NA PRAIA DA PONTA NEGRA, APÓS ALGUMA TEMPO A MÃE APÁRECEU ENTÃO A EQUIPE ENTREGOU A CRIANÇA NO POSTO DOS BOMBEIROS. | K13: LUIZ RICARDO DE OLIVEIRA ALBUQUERQUE
A14: Outras ocorrências | B14: Atendimento ao banhista | C14: 2023 | D14: Jan | E14: 44927 | G14: 44927 | H14: 44927 | I14: PACIENTE: Betsabata Aguilera del Valle. 46 anos CELULAR: 92 98631 6012 ENDEREÇO: Lírio do vale - beco das flores ATENDIMENTO PELA GU DE APH, FOI AVALIADA PELO TEN BM REATEGUI APRESENTOU MAL SÚBITO, TAQUICARDIA. ENCAMINHADA AO SPA JOVENTINA DIAS PELA UR 19 | K14: LUIZ RICARDO DE OLIVEIRA ALBUQUERQUE
A15: Outras ocorrências | B15: Atendimento pré-hospitalar transporte de paciente | C15: 2023 | D15: Jan | E15: 44927 | G15: 44927 | H15: 44927 | I15: PACIENTE: Betsabata Aguilera del Valle. 46 anos CELULAR: 92 98631 6012 ENDEREÇO: Lírio do vale - beco das flores ATENDIMENTO PELA GU DE APH, FOI AVALIADA PELO TEN BM REATEGUI APRESENTOU MAL SÚBITO, TAQUICARDIA. ENCAMINHADA AO SPA JOVENTINA DIAS PELA UR 19 | K15: LUIZ RICARDO DE OLIVEIRA ALBUQUERQUE
A16: Outras ocorrências | B16: Corte de algema / anel / outros | C16: 2023 | D16: Jan | E16: 44927 | G16: 44927 | I16: CORTE DE ANEL EM UNIDADE HOSPITALAR HPS JOÃO LUCIO PACIENTE: CLAUDIO RERIVELTON LIRA - 29 a ANEL TIPO ALIANÇA EM MÃO ESQUERDA CLÍNICA POLITRAUMA HPS JOÃO LÚCIO ENFº ADONILSON DA ENFª POLITRAUMA - 3249 9407 1º BI; PB ZUMBI; VTR ABT-30 À COMANDO DO SGT BM GENTIL. DESLOCA ATÉ AO HPS JOÃO LÚCIO, ATENDER OCORRÊNCIA DE CORTE DE ANEL, SETOR DE POLITRALMA. SOLICITANTE: ENFERMEIRO ADONILSON 3249-9407. PACIENTE: CLÁUDIO RERIVELTON LIRA. 29 ANOS. ANEL TIPO ALIANÇA, DEDO ANELAR ESQUERDO. SERVIÇO DO DIA 01.01.2024 / 2º TURNO CMT DE SOCORRO: 2º TEN BM VALÉRIO CONTROLADOR COBOM: 1º TEN BM R. LIRA | K16: Rozivaldo de Souza Lira
A17: Outras ocorrências | B17: Captura / resgate de animais | C17: 2023 | D17: Jan | E17: 44927 | G17: 44927 | I17: RUA PADRE RAMIM, N 8, ZUMBI 2 PROX A ESCOLA MUNICIPAL ANITA GARIBALDI 99398-3070 - HELENA COSTA CACHORRO PRESO ENTRE DUAS PAREDES. 1º BI; PB ZUMBI; VTR ABT-30 À COMANDO DO SGT BM GENTIL. DESLOCA ATÉ AO HPS JOÃO LÚCIO, ATENDER OCORRÊNCIA DE RESDGATE DE ANIMAL TIPO CACHORRO, O MESMO ESTÁ PRESO ENTRE DUAS PAREDES, CACHORRO TIPO VIRA-LATA. SOLICITANTE: PROPRIETÁRIA DA 1ª CASA: SRA. HELENA ZACARIAS DA COSTA. 64 ANOS. CPF: 416.188.232-72 TEL: 99999-7739. PROPRIETÁRIA DA 2ª CASA: SRA. OTARCILA ALMEIDA DE FREITAS. 80 ANOS. CPF: 052.644.642-00 CEL: 99466-9991. AÇÃO DO BOMBEIRO: NÃO FOI POSSÍVEL A REMOÇÃO DO ANIMAL MEDIANTE CAMBÃO, A SRA OTARCILA AUTORIZOU A GUARNIÇÃO QUEBRAR O MURO DA DISPENSA DE SUA CASA, FOI QUEBRADO CERCA DE 50cm LARGURA E 50cm DE ALTURA, DO MURO DA MESMA. O ANIMAL FOI RESGATADO COM VIDA E ENTREGUE À PROPRIETÁRIA DO MESMO. LOCAL EM SEGURANÇA, A VTR ABT-30 RETRAI AO PB DE ORIGEM. SERVIÇO DO DIA 01.01.2024 / 2º TURNO CMT DE SOCORRO: 2º TEN BM VALÉRIO CONTROLADOR COBOM: 1º TEN BM R. LIRA | K17: Rozivaldo de Souza Lira
A18: Outras ocorrências | B18: Corte de algema / anel / outros | C18: 2023 | D18: Jan | E18: 44927 | G18: 44927 | I18: CORTE DE ANEL NO CIS GRANDE CIRCULAR. 1º BI; PB CIS GC; A GUARNIÇÃO DA VTR ABT-25 REALIZOU CORTE DE ANEL NO DEDO ANELAR ESQUERDO. MATERIAL: ROMMANEL. SOLICITANTE: MAYARA DE SOUZA SILVA. 24 ANOS. FONE: 99411-4819 RG: 3154583-1 ENDEREÇO: RUA JACARANDÁ. BAIRRO: JORGE TEIXEIRA SERVIÇO DO DIA 01.01.2024 / 2º TURNO CMT DE SOCORRO: 2º TEN BM VALÉRIO CONTROLADOR COBOM: 1º TEN BM R. LIRA | K18: Rozivaldo de Souza Lira
A19: Outras ocorrências | B19: Prevenção - outros | C19: 2023 | D19: Jan | E19: 44928 | G19: 44928 | H19: 44929 | I19: SEG NOS POSTOS DO CBMAM SGT TIAGO RAMIRES 1829 08:00 20:00 12:00 QCG 159/CSM/2022 GARAGISTA SGT SILVA 776 07:30 19:30 12:00 CIS G. CIRCULAR 002/1°BI/2024 REFORÇO DE GU CB RODRIGO VIEIRA 1152 07:00 17:00 10:00 QGC 001/CBC/2024 CORTE DE ÁRVORE ST ARILSON 572 07:30 19:30 12:00 SCI-EG 003/SCI-EG/2024 REFORÇO DE EQUIPAGEM ST HELDER 738 07:30 19:30 12:00 SCI-EG 003/SCI-EG/2024 REFORÇO DE EQUIPAGEM CB DIEGO FALCÃO 1266 07:30 19:30 12:00 SCI-EG 003/SCI-EG/2024 REFORÇO DE EQUIPAGEM SGT LAURA 766 08:00 20:00 12:00 PB RODOVIÁRIA 960/BBE/2022 REFORÇO DE GU ST PABLO 692 08:00 20:00 12:00 BIFMA 001/BIFMA/2024 REFORÇO DE GU TEN EDITH 1441 23:00 04:00 05:00 SHOPPING PHLIPPE DAOU 151/DS/2022 OPERÇÃO REVEILLON SGT LUCIANE MOTA 1544 23:00 04:00 05:00 SHOPPING PHLIPPE DAOU 151/DS/2022 OPERÇÃO REVEILLON SGT SARA DIANE 1561 23:00 04:00 05:00 SHOPPING PHLIPPE DAOU 151/DS/2022 OPERÇÃO REVEILLON SGT SARA 1563 23:00 04:00 05:00 SHOPPING PHLIPPE DAOU 151/DS/2022 OPERÇÃO REVEILLON SGT JUCILEIDA 1705 23:00 04:00 05:00 SHOPPING PHLIPPE DAOU 151/DS/2022 OPERÇÃO REVEILLON SGT IBERNON 1607 23:00 04:00 05:00 SHOPPING PHLIPPE DAOU 151/DS/2022 OPERÇÃO REVEILLON SGT SILVANDO 1679 23:00 04:00 05:00 SHOPPING PHLIPPE DAOU 151/DS/2022 OPERÇÃO REVEILLON SGT IRLENE 1594 23:00 04:00 05:00 SHOPPING PHLIPPE DAOU 151/DS/2022 OPERÇÃO REVEILLON SGT EVANGELISTA 699 14:00 19:00 05:00 TEATRO AMAZONAS 409/BIFMA/2022 SOLENIDADE DE POSSE DO TJAM CB MARCUS 1017 14:00 19:00 05:00 TEATRO AMAZONAS 409/BIFMA/2022 SOLENIDADE DE POSSE DO TJAM CB LUCIANA 1774 13:00 18:00 05:00 QCG 001/AJAI/2024 ATENDER PRAZOS JUDICIAIS SGT HELOISA PAIVA 1717 15:00 23:00 08:00 TEATRO AMAZONAS 125/COBOM/2022 SOLENIDADE DE POSSE DO TJAM ST AURÉLIO 618 14:00 23:00 09:00 TEATRO AMAZONAS 004/1°BI/2024 SOLENIDADE DE POSSE DO TJAM SGT ARILDO 760 14:00 23:00 09:00 TEATRO AMAZONAS 004/1°BI/2024 SOLENIDADE DE POSSE DO TJAM CB PETILLO 1130 14:00 23:00 09:00 TEATRO AMAZONAS 004/1°BI/2024 VOLANTE ATP- 07 CB BARBOSA 1097 15:00 23:00 08:00 TEATRO AMAZONAS 956/BBE/2022 SOLENIDADE DE POSSE DO TJAM CB SARMENTO 1105 15:00 23:00 08:00 TEATRO AMAZONAS 956/BBE/2022 SOLENIDADE DE POSSE DO TJAM CB MARCUS FREIRE 1189 15:00 23:00 08:00 TEATRO AMAZONAS 239/CIACCG/2022 SOLENIDADE DE POSSE DO TJAM SGT JEFERSON SOUZA 1533 18:00 06:00 12:00 QCG 235/CIACG/23 ATALAIA CB S. RODRIGUES 1003 20:00 08:00 12:00 PB RODOVIÁRIA 960/BBE/22 REFORÇO DE GU SGT SILLAS JUNIOR 715 20:00 08:00 12:00 QCG 159/CSM/22 GARAGISTA CB GETLYN 1025 20:00 08:00 12:00 DAT 181/DAT/22 PERMANÊNCIA CB RAFAEL LIMA 1040 19:30 07:30 12:00 CIS G. CIRCULAR 003/1°BI/23 REFORÇO DE GU CB ASSUNÇÃO 1147 19:30 07:30 12:00 SCI - EG 04/SCI-EG/23 REFORÇO DE GU CB GERÔNIMO 1202 19:30 07:30 12:00 SCI - EG 04/SCI-EG/23 REFORÇO DE GU CB GENIVALDO 1193 19:30 07:30 12:00 SCI - EG 04/SCI-EG/23 REFORÇO DE GU SERVIÇO DO DIA 02.01.2024 / 1º TURNO CMT DE SOCORRO: 2º TEN BM EDUARDO ARAÚJO CONTROLADOR COBOM: 1º TEN BM R. LIRA | K19: LUIZ RICARDO DE OLIVEIRA ALBUQUERQUE
A20: Incêndio em edificação | B20: Incêndio em apartamento | C20: 2023 | D20: Jan | E20: 44928 | G20: 44928 | I20: PRINCIPIO DE INCENDIO EM APARTAMENTO. BBE; PB CENTRAL; VTR ABT-31 À COMANDO DO CB BM ROBISON. DESLOCA AO LOCAL SOLICITADO, ATNDER OCORRÊNCIA DE PRINCÍPIO DE INCÊNDIO EM APARTAMENTO. TRATA-SE DE UM CURTO ELÉTRICO NA GELADEIRA, QUE PROVOCOU UM FOCO DE INCÊNDIO CONTIDO PELOS PRÓPRIOS MORADORES, QUE À POSERAM NA ÁREA EXTERNA DA CASA. SOLICITANTE: RONELIO CARDOSO DE LIMA. 40 ANOS. TEL: 92 99172-7579 RG: 1519219-9 SSP/AM CPF: 524.562.632-91 NARRATIVA: PRINCÍPIO DE INCÊNDIO NA COZINHA INICIADO NA PARTE DE TRÁS DA GELADEIRA. O SOLICITANTE FEZ A RETIRADA DA GELADEIRA PARA ÁREA EXTERNA E EXTINGUIU AS CHAMAS POR RESFRIAMENTO. LOCAL EM SEGURANÇA, A VTR ABT-31 RETRAI AO PB DE ORIGEM. SERVIÇO DO DIA 02.01.2024 / 1º TURNO CMT DE SOCORRO: 2º TEN BM EDUARDO ARAÚJO CONTROLADOR COBOM: 1º TEN BM R. LIRA | K20: Rozivaldo de Souza Lira
A21: Outras ocorrências | B21: Corte de árvore | C21: 2023 | D21: Jan | E21: 44928 | G21: 44928 | I21: CORTE DE ÁRVORE DE MÉDIO PORTE TIPO PITOMBEIRA, RUA SANTA ISABEL, 446 - COMPENSA. CBC; VTR AR-42 COMPOSTA PELOS MILITARES, CB BM J. NUNES, CB BM IRINILDO E CB BM RODRIGO VIEIRA. DESOCA PARA CUMPRIR MISSÃO DE CORTE DE ÁRVORE TIPO PITIMBEIRA. SOLICITANTE: ITAMAR. TEL: 99134-6750. CORTE DA ÁRVORE PARCIAL, NÃO FINALIZADA POR TER CHOVIDO MUITO NA ÁREA, FICANDO APENAS O TRONCO, A VTR AR-42 RETRA AO PB DE ORIGEM. SERVIÇO DO DIA 02.01.2024 / 1º TURNO CMT DE SOCORRO: 2º TEN BM EDUARDO ARAÚJO CONTROLADOR COBOM: 1º TEN BM R. LIRA | K21: Rozivaldo de Souza Lira
A22: Outras ocorrências | B22: Vistoria em árvore - situação de risco | C22: 2023 | D22: Jan | E22: 44928 | G22: 44928 | I22: SENHORA VERICA / LOGISTICA, SOLICITOU APOIO PARA UMA ARVORE QUE ESTA EM RISCO DE TOMBAMENTO TOTAL, PARTE DA ARVORE CAIU ENTRE OS PREDIOS DO HEMOAM E ANTIGO HOSPICIO EDUARDO RIBEIRO. BBE; PB RODOVIÁRIA; VTR ABT-29 À COMANDO DA SGT BM LAURA. DESLOCA ATÉ O HEMOAM, ATENDER OCORRÊNCIA DE VISTORIA/CORTE DE ÁRVORE. TRATA-SE DE DOIS GALHOS DE GRANDE PORTE QUE CAÍRAM E ESTÃO OBSTRUINDO A PASSAGEM DE VEÍCULOS. AÇÃO DA GUARNIÇÃO: RETIRADO OS GALHOS DO MEIO DA VIA, SEM ALTERAÇÃO. A VTR ABT-29 RETRAI AO PB DE ORIGEM. SERVIÇO DO DIA 02.01.2024 / 1º TURNO CMT DE SOCORRO: 2º TEN BM EDUARDO ARAÚJO CONTROLADOR COBOM: 1º TEN BM R. LIRA | K22: Rozivaldo de Souza Lira
A23: Outras ocorrências | B23: Prevenção em festas / eventos diversos | C23: 2023 | D23: Jan | E23: 44928 | G23: 44928 | I23: ORDEM DE SERVIÇO 294/CBC/2022 EVENTO: POSSE DA NOVA DIRETORIA DO TRIBUNAL DE JUSTIÇA DO AMAZONAS. MISSÃO: REALIZAR PREVENÇÃO EM EVENTOS, ATENDIMENTO DE URG¿NCIA E EMERGÊNCIAS, DATA; 02/01/2024 HORA: 13:30 ÀS 20:00 LOCAL: TEATRO AMAZONAS / PALÁCIO RIO NEGRO RECURSOS EMPREGADOS: 01 SUPERIOR DE DIA, 01 UR, 02 BM DO BBE, 02 BM DO 1° BI. COMANDANTE DE SOCORRO, VIATURA AR-55, GREM; PB JAGUAR; VTR UR-19 DESLOCA AO TEATRO AMAZONAS, CUMPRIR PLANO DE OPERAÇÃO Nº 294-CBC/2022. EVENTO: POSSE DA NOVA DIRETORIA DO TRIBUNAL DE JUSTIÇA DO AMAZONAS, TJAM. MISSÃO: REALIZAR PREVENÇÃO EM EVENTO, ATENDIMENTO DE URGÊNCIA/EMERGÊNCIA. LOGO APÓS CUMPRIR SEGUNDO PONTO DE PREVENÇÃO, NO PALÁCIO RIO NEGRO, JANTAR DAS AUTORIDADES. EM SEGUIDA DESLOCARAM PARA O CENTRO DE CONVENÇÕES ONDE PERMANECERAM ATÉ O TÉRMINO DO EVENTO. | K23: LUIZ RICARDO DE OLIVEIRA ALBUQUERQUE
A24: Outras ocorrências | B24: Corte de algema / anel / outros | C24: 2023 | D24: Jan | E24: 44928 | G24: 44928 | I24: CORTE DE ANEL REGISTRADO NO BBE. BBE; PB RODOVIÁRIA; A GUARNIÇÃO DA VTR ABT-29 ATENDEU UMA OCORRÊNCIA DE CORTE DE ANEL. DEDO ANELAR ESQUERDO. NOME: JÚLIA EVELIN DE OLIVEIRA GOMES. 13 ANOS. RG: 3782635-2 MÃE: JOSIANE SILVA DE OLIVEIRA. ENDEREÇO. RUA INDEPENDÊNCIA N° 34 BAIRRO REDENÇÃO. SERVIÇO DO DIA 02.01.2024 / 1º TURNO CMT DE SOCORRO: 2º TEN BM EDUARDO ARAÚJO CONTROLADOR COBOM: 1º TEN BM R. LIRA | K24: Rozivaldo de Souza Lira
A25: Outras ocorrências | B25: Incêndio em veículo | C25: 2023 | D25: Jan | E25: 44929 | G25: 44929 | H25: 44929 | I25: FOGO EM VEÍCULO - CORSA ANTIGO RUA GUARACIABA, 141 - COLONIA TERRA NOVA PRÓXIMO AO MERCADINHO BEATRIZ BRUNA - 98405 5001 BIFMA, PARQUE SUMAUMA, VIATURA ABT-32, SOB O COMANDO DO ST BM PABLO DESLOCARAM PARA INCENCIO EM VEÍCULO MODELO CELTA DE COR PRATA, PLACA JWY-0112, PROPRIETÁRIO: MARCELINO DA SILVA, 49 ANOS, RG 47397071287, CONTATO 99441-2338, A EQUIPE INFORMOU QUE O FOGO DEU INÍCIO PELA BATERIA, A VIZINHANÇA CONSEGUIU CONTROLAR AS CHAMAS, A EQUIPE REALIZOU O ISOLAMENTO DA BATERIA DO VEÍCULO, HOUVE DANOS PARCIAL NO COMPARTIMENTO DO MOTOR SOMENTE. | K25: LUIZ RICARDO DE OLIVEIRA ALBUQUERQUE
